ERROR:__main__:Connection error.
Traceback (most recent call last):
  File "C:\Users\tianq\Desktop\LIGN 169\Balancing-The-Flow\scripts\.venv\Lib\site-packages\httpx\_transports\default.py", line 101, in map_httpcore_exceptions
    yield
  File "C:\Users\tianq\Desktop\LIGN 169\Balancing-The-Flow\scripts\.venv\Lib\site-packages\httpx\_transports\default.py", line 250, in handle_request
    resp = self._pool.handle_request(req)
           ^^^^^^^^^^^^^^^^^^^^^^^^^^^^^^
  File "C:\Users\tianq\Desktop\LIGN 169\Balancing-The-Flow\scripts\.venv\Lib\site-packages\httpcore\_sync\connection_pool.py", line 256, in handle_request
    raise exc from None
  File "C:\Users\tianq\Desktop\LIGN 169\Balancing-The-Flow\scripts\.venv\Lib\site-packages\httpcore\_sync\connection_pool.py", line 236, in handle_request
    response = connection.handle_request(
               ^^^^^^^^^^^^^^^^^^^^^^^^^^
  File "C:\Users\tianq\Desktop\LIGN 169\Balancing-The-Flow\scripts\.venv\Lib\site-packages\httpcore\_sync\connection.py", line 101, in handle_request
    raise exc
  File "C:\Users\tianq\Desktop\LIGN 169\Balancing-The-Flow\scripts\.venv\Lib\site-packages\httpcore\_sync\connection.py", line 78, in handle_request
    stream = self._connect(request)
             ^^^^^^^^^^^^^^^^^^^^^^
  File "C:\Users\tianq\Desktop\LIGN 169\Balancing-The-Flow\scripts\.venv\Lib\site-packages\httpcore\_sync\connection.py", line 124, in _connect
    stream = self._network_backend.connect_tcp(**kwargs)
             ^^^^^^^^^^^^^^^^^^^^^^^^^^^^^^^^^^^^^^^^^^^
  File "C:\Users\tianq\Desktop\LIGN 169\Balancing-The-Flow\scripts\.venv\Lib\site-packages\httpcore\_backends\sync.py", line 207, in connect_tcp
    with map_exceptions(exc_map):
         ^^^^^^^^^^^^^^^^^^^^^^^
  File "C:\Users\tianq\AppData\Local\Programs\Python\Python312\Lib\contextlib.py", line 158, in __exit__
    self.gen.throw(value)
  File "C:\Users\tianq\Desktop\LIGN 169\Balancing-The-Flow\scripts\.venv\Lib\site-packages\httpcore\_exceptions.py", line 14, in map_exceptions
    raise to_exc(exc) from exc
httpcore.ConnectError: [WinError 10061] No connection could be made because the target machine actively refused it

The above exception was the direct cause of the following exception:

Traceback (most recent call last):
  File "C:\Users\tianq\Desktop\LIGN 169\Balancing-The-Flow\scripts\.venv\Lib\site-packages\openai\_base_client.py", line 955, in _request
    response = self._client.send(
               ^^^^^^^^^^^^^^^^^^
  File "C:\Users\tianq\Desktop\LIGN 169\Balancing-The-Flow\scripts\.venv\Lib\site-packages\httpx\_client.py", line 914, in send
    response = self._send_handling_auth(
               ^^^^^^^^^^^^^^^^^^^^^^^^^
  File "C:\Users\tianq\Desktop\LIGN 169\Balancing-The-Flow\scripts\.venv\Lib\site-packages\httpx\_client.py", line 942, in _send_handling_auth
    response = self._send_handling_redirects(
               ^^^^^^^^^^^^^^^^^^^^^^^^^^^^^^
  File "C:\Users\tianq\Desktop\LIGN 169\Balancing-The-Flow\scripts\.venv\Lib\site-packages\httpx\_client.py", line 979, in _send_handling_redirects
    response = self._send_single_request(request)
               ^^^^^^^^^^^^^^^^^^^^^^^^^^^^^^^^^^
  File "C:\Users\tianq\Desktop\LIGN 169\Balancing-The-Flow\scripts\.venv\Lib\site-packages\httpx\_client.py", line 1014, in _send_single_request
    response = transport.handle_request(request)
               ^^^^^^^^^^^^^^^^^^^^^^^^^^^^^^^^^
  File "C:\Users\tianq\Desktop\LIGN 169\Balancing-The-Flow\scripts\.venv\Lib\site-packages\httpx\_transports\default.py", line 249, in handle_request
    with map_httpcore_exceptions():
         ^^^^^^^^^^^^^^^^^^^^^^^^^
  File "C:\Users\tianq\AppData\Local\Programs\Python\Python312\Lib\contextlib.py", line 158, in __exit__
    self.gen.throw(value)
  File "C:\Users\tianq\Desktop\LIGN 169\Balancing-The-Flow\scripts\.venv\Lib\site-packages\httpx\_transports\default.py", line 118, in map_httpcore_exceptions
    raise mapped_exc(message) from exc
httpx.ConnectError: [WinError 10061] No connection could be made because the target machine actively refused it

The above exception was the direct cause of the following exception:

Traceback (most recent call last):
  File "C:\Users\tianq\Desktop\LIGN 169\Balancing-The-Flow\scripts\prompter.py", line 54, in <module>
    completion = CLIENT.chat.completions.create(
                 ^^^^^^^^^^^^^^^^^^^^^^^^^^^^^^^
  File "C:\Users\tianq\Desktop\LIGN 169\Balancing-The-Flow\scripts\.venv\Lib\site-packages\openai\_utils\_utils.py", line 279, in wrapper
    return func(*args, **kwargs)
           ^^^^^^^^^^^^^^^^^^^^^
  File "C:\Users\tianq\Desktop\LIGN 169\Balancing-The-Flow\scripts\.venv\Lib\site-packages\openai\resources\chat\completions\completions.py", line 879, in create
    return self._post(
           ^^^^^^^^^^^
  File "C:\Users\tianq\Desktop\LIGN 169\Balancing-The-Flow\scripts\.venv\Lib\site-packages\openai\_base_client.py", line 1242, in post
    return cast(ResponseT, self.request(cast_to, opts, stream=stream, stream_cls=stream_cls))
                           ^^^^^^^^^^^^^^^^^^^^^^^^^^^^^^^^^^^^^^^^^^^^^^^^^^^^^^^^^^^^^^^^^
  File "C:\Users\tianq\Desktop\LIGN 169\Balancing-The-Flow\scripts\.venv\Lib\site-packages\openai\_base_client.py", line 919, in request
    return self._request(
           ^^^^^^^^^^^^^^
  File "C:\Users\tianq\Desktop\LIGN 169\Balancing-The-Flow\scripts\.venv\Lib\site-packages\openai\_base_client.py", line 979, in _request
    return self._retry_request(
           ^^^^^^^^^^^^^^^^^^^^
  File "C:\Users\tianq\Desktop\LIGN 169\Balancing-The-Flow\scripts\.venv\Lib\site-packages\openai\_base_client.py", line 1057, in _retry_request
    return self._request(
           ^^^^^^^^^^^^^^
  File "C:\Users\tianq\Desktop\LIGN 169\Balancing-The-Flow\scripts\.venv\Lib\site-packages\openai\_base_client.py", line 979, in _request
    return self._retry_request(
           ^^^^^^^^^^^^^^^^^^^^
  File "C:\Users\tianq\Desktop\LIGN 169\Balancing-The-Flow\scripts\.venv\Lib\site-packages\openai\_base_client.py", line 1057, in _retry_request
    return self._request(
           ^^^^^^^^^^^^^^
  File "C:\Users\tianq\Desktop\LIGN 169\Balancing-The-Flow\scripts\.venv\Lib\site-packages\openai\_base_client.py", line 989, in _request
    raise APIConnectionError(request=request) from err
openai.APIConnectionError: Connection error.
ERROR:__main__:Request timed out.
Traceback (most recent call last):
  File "C:\Users\tianq\Desktop\LIGN 169\Balancing-The-Flow\scripts\.venv\Lib\site-packages\httpx\_transports\default.py", line 101, in map_httpcore_exceptions
    yield
  File "C:\Users\tianq\Desktop\LIGN 169\Balancing-The-Flow\scripts\.venv\Lib\site-packages\httpx\_transports\default.py", line 250, in handle_request
    resp = self._pool.handle_request(req)
           ^^^^^^^^^^^^^^^^^^^^^^^^^^^^^^
  File "C:\Users\tianq\Desktop\LIGN 169\Balancing-The-Flow\scripts\.venv\Lib\site-packages\httpcore\_sync\connection_pool.py", line 256, in handle_request
    raise exc from None
  File "C:\Users\tianq\Desktop\LIGN 169\Balancing-The-Flow\scripts\.venv\Lib\site-packages\httpcore\_sync\connection_pool.py", line 236, in handle_request
    response = connection.handle_request(
               ^^^^^^^^^^^^^^^^^^^^^^^^^^
  File "C:\Users\tianq\Desktop\LIGN 169\Balancing-The-Flow\scripts\.venv\Lib\site-packages\httpcore\_sync\connection.py", line 103, in handle_request
    return self._connection.handle_request(request)
           ^^^^^^^^^^^^^^^^^^^^^^^^^^^^^^^^^^^^^^^^
  File "C:\Users\tianq\Desktop\LIGN 169\Balancing-The-Flow\scripts\.venv\Lib\site-packages\httpcore\_sync\http11.py", line 136, in handle_request
    raise exc
  File "C:\Users\tianq\Desktop\LIGN 169\Balancing-The-Flow\scripts\.venv\Lib\site-packages\httpcore\_sync\http11.py", line 106, in handle_request
    ) = self._receive_response_headers(**kwargs)
        ^^^^^^^^^^^^^^^^^^^^^^^^^^^^^^^^^^^^^^^^
  File "C:\Users\tianq\Desktop\LIGN 169\Balancing-The-Flow\scripts\.venv\Lib\site-packages\httpcore\_sync\http11.py", line 177, in _receive_response_headers
    event = self._receive_event(timeout=timeout)
            ^^^^^^^^^^^^^^^^^^^^^^^^^^^^^^^^^^^^
  File "C:\Users\tianq\Desktop\LIGN 169\Balancing-The-Flow\scripts\.venv\Lib\site-packages\httpcore\_sync\http11.py", line 217, in _receive_event
    data = self._network_stream.read(
           ^^^^^^^^^^^^^^^^^^^^^^^^^^
  File "C:\Users\tianq\Desktop\LIGN 169\Balancing-The-Flow\scripts\.venv\Lib\site-packages\httpcore\_backends\sync.py", line 126, in read
    with map_exceptions(exc_map):
         ^^^^^^^^^^^^^^^^^^^^^^^
  File "C:\Users\tianq\AppData\Local\Programs\Python\Python312\Lib\contextlib.py", line 158, in __exit__
    self.gen.throw(value)
  File "C:\Users\tianq\Desktop\LIGN 169\Balancing-The-Flow\scripts\.venv\Lib\site-packages\httpcore\_exceptions.py", line 14, in map_exceptions
    raise to_exc(exc) from exc
httpcore.ReadTimeout: timed out

The above exception was the direct cause of the following exception:

Traceback (most recent call last):
  File "C:\Users\tianq\Desktop\LIGN 169\Balancing-The-Flow\scripts\.venv\Lib\site-packages\openai\_base_client.py", line 955, in _request
    response = self._client.send(
               ^^^^^^^^^^^^^^^^^^
  File "C:\Users\tianq\Desktop\LIGN 169\Balancing-The-Flow\scripts\.venv\Lib\site-packages\httpx\_client.py", line 914, in send
    response = self._send_handling_auth(
               ^^^^^^^^^^^^^^^^^^^^^^^^^
  File "C:\Users\tianq\Desktop\LIGN 169\Balancing-The-Flow\scripts\.venv\Lib\site-packages\httpx\_client.py", line 942, in _send_handling_auth
    response = self._send_handling_redirects(
               ^^^^^^^^^^^^^^^^^^^^^^^^^^^^^^
  File "C:\Users\tianq\Desktop\LIGN 169\Balancing-The-Flow\scripts\.venv\Lib\site-packages\httpx\_client.py", line 979, in _send_handling_redirects
    response = self._send_single_request(request)
               ^^^^^^^^^^^^^^^^^^^^^^^^^^^^^^^^^^
  File "C:\Users\tianq\Desktop\LIGN 169\Balancing-The-Flow\scripts\.venv\Lib\site-packages\httpx\_client.py", line 1014, in _send_single_request
    response = transport.handle_request(request)
               ^^^^^^^^^^^^^^^^^^^^^^^^^^^^^^^^^
  File "C:\Users\tianq\Desktop\LIGN 169\Balancing-The-Flow\scripts\.venv\Lib\site-packages\httpx\_transports\default.py", line 249, in handle_request
    with map_httpcore_exceptions():
         ^^^^^^^^^^^^^^^^^^^^^^^^^
  File "C:\Users\tianq\AppData\Local\Programs\Python\Python312\Lib\contextlib.py", line 158, in __exit__
    self.gen.throw(value)
  File "C:\Users\tianq\Desktop\LIGN 169\Balancing-The-Flow\scripts\.venv\Lib\site-packages\httpx\_transports\default.py", line 118, in map_httpcore_exceptions
    raise mapped_exc(message) from exc
httpx.ReadTimeout: timed out

The above exception was the direct cause of the following exception:

Traceback (most recent call last):
  File "C:\Users\tianq\Desktop\LIGN 169\Balancing-The-Flow\scripts\prompter.py", line 54, in <module>
    completion = CLIENT.chat.completions.create(
                 ^^^^^^^^^^^^^^^^^^^^^^^^^^^^^^^
  File "C:\Users\tianq\Desktop\LIGN 169\Balancing-The-Flow\scripts\.venv\Lib\site-packages\openai\_utils\_utils.py", line 279, in wrapper
    return func(*args, **kwargs)
           ^^^^^^^^^^^^^^^^^^^^^
  File "C:\Users\tianq\Desktop\LIGN 169\Balancing-The-Flow\scripts\.venv\Lib\site-packages\openai\resources\chat\completions\completions.py", line 879, in create
    return self._post(
           ^^^^^^^^^^^
  File "C:\Users\tianq\Desktop\LIGN 169\Balancing-The-Flow\scripts\.venv\Lib\site-packages\openai\_base_client.py", line 1242, in post
    return cast(ResponseT, self.request(cast_to, opts, stream=stream, stream_cls=stream_cls))
                           ^^^^^^^^^^^^^^^^^^^^^^^^^^^^^^^^^^^^^^^^^^^^^^^^^^^^^^^^^^^^^^^^^
  File "C:\Users\tianq\Desktop\LIGN 169\Balancing-The-Flow\scripts\.venv\Lib\site-packages\openai\_base_client.py", line 919, in request
    return self._request(
           ^^^^^^^^^^^^^^
  File "C:\Users\tianq\Desktop\LIGN 169\Balancing-The-Flow\scripts\.venv\Lib\site-packages\openai\_base_client.py", line 964, in _request
    return self._retry_request(
           ^^^^^^^^^^^^^^^^^^^^
  File "C:\Users\tianq\Desktop\LIGN 169\Balancing-The-Flow\scripts\.venv\Lib\site-packages\openai\_base_client.py", line 1057, in _retry_request
    return self._request(
           ^^^^^^^^^^^^^^
  File "C:\Users\tianq\Desktop\LIGN 169\Balancing-The-Flow\scripts\.venv\Lib\site-packages\openai\_base_client.py", line 964, in _request
    return self._retry_request(
           ^^^^^^^^^^^^^^^^^^^^
  File "C:\Users\tianq\Desktop\LIGN 169\Balancing-The-Flow\scripts\.venv\Lib\site-packages\openai\_base_client.py", line 1057, in _retry_request
    return self._request(
           ^^^^^^^^^^^^^^
  File "C:\Users\tianq\Desktop\LIGN 169\Balancing-The-Flow\scripts\.venv\Lib\site-packages\openai\_base_client.py", line 974, in _request
    raise APITimeoutError(request=request) from err
openai.APITimeoutError: Request timed out.
